import pytest
from definition_b41b8a76bca84b65a6673668fafd0175 import generate_computational_graph_visualization

@pytest.fixture
def mock_matplotlib(monkeypatch):
    class MockFigure:
        def savefig(self, filename):
            pass  # Mock saving the figure

    class MockPlot:
        def figure(self, *args, **kwargs):
            return MockFigure()

        def gca(self, *args, **kwargs):
            return MockPlot()

        def plot(self, *args, **kwargs):
            pass

        def title(self, *args, **kwargs):
            pass

        def xlabel(self, *args, **kwargs):
            pass

        def ylabel(self, *args, **kwargs):
            pass

        def show(self, *args, **kwargs):
            pass

    monkeypatch.setattr("matplotlib.pyplot", MockPlot())


@pytest.mark.usefixtures("mock_matplotlib")
class TestGenerateComputationalGraphVisualization:

    def test_empty_graph_data(self):
        try:
            generate_computational_graph_visualization({})
        except Exception as e:
            assert False, f"Unexpected exception: {e}"

    def test_simple_graph_data(self):
        graph_data = {"nodes": ["A", "B"], "edges": [("A", "B")]}
        try:
            generate_computational_graph_visualization(graph_data)
        except Exception as e:
            assert False, f"Unexpected exception: {e}"

    def test_complex_graph_data(self):
        graph_data = {
            "nodes": ["A", "B", "C", "D"],
            "edges": [("A", "B"), ("B", "C"), ("C", "D")],
        }
        try:
            generate_computational_graph_visualization(graph_data)
        except Exception as e:
            assert False, f"Unexpected exception: {e}"

    def test_invalid_graph_data_type(self):
        with pytest.raises(TypeError):
             generate_computational_graph_visualization("invalid")

    def test_graph_data_with_numerical_nodes(self):
        graph_data = {"nodes": [1, 2, 3], "edges": [(1, 2), (2, 3)]}
        try:
            generate_computational_graph_visualization(graph_data)
        except Exception as e:
            assert False, f"Unexpected exception: {e}"
